<?xml version="1.0" ?><!-- =================================================================================== --><!-- |    This document was autogenerated by xacro from /root/ros2_ws/install/robotsim_package/share/robotsim_package/urdf/robotsim2.urdf.xacro | --><!-- |    EDITING THIS FILE BY HAND IS NOT RECOMMENDED                                 | --><!-- =================================================================================== --><robot name="robotsim2"><link name="base_link"><visual><geometry><box size="0.3 0.3 0.1"/></geometry><material name="white"><color rgba="1 1 1 1"/></material></visual><collision><geometry><box size="0.3 0.3 0.1"/></geometry></collision><inertial><mass value="4"/><inertia ixx="0.1" ixy="0.0" ixz="0.0" iyy="0.1" iyz="0.0" izz="0.1"/></inertial></link><link name="front_right_wheel"><visual><geometry><cylinder length="0.04" radius="0.05"/></geometry><material name="black"><color rgba="0 0 0 1"/></material></visual><collision><geometry><cylinder length="0.04" radius="0.05"/></geometry></collision><inertial><mass value="0.25"/><inertia ixx="0.001" ixy="0" ixz="0" iyy="0.001" iyz="0" izz="0.001"/></inertial></link><joint name="front_right_wheel_joint" type="continuous"><parent link="base_link"/><child link="front_right_wheel"/><origin rpy="1.5707963267948966 0 0" xyz="0.15 -0.16999999999999998 -0.04"/><axis xyz="0 0 1"/></joint><transmission name="front_right_wheel_trans"><type>transmission_interface/SimpleTransmission</type><joint name="front_right_wheel_joint"><hardwareInterface>hardware_interface/VelocityJointInterface</hardwareInterface></joint><actuator name="front_right_wheel_motor"><mechanicalReduction>1</mechanicalReduction></actuator></transmission><link name="front_left_wheel"><visual><geometry><cylinder length="0.04" radius="0.05"/></geometry><material name="black"><color rgba="0 0 0 1"/></material></visual><collision><geometry><cylinder length="0.04" radius="0.05"/></geometry></collision><inertial><mass value="0.25"/><inertia ixx="0.001" ixy="0" ixz="0" iyy="0.001" iyz="0" izz="0.001"/></inertial></link><joint name="front_left_wheel_joint" type="continuous"><parent link="base_link"/><child link="front_left_wheel"/><origin rpy="1.5707963267948966 0 0" xyz="0.15 0.16999999999999998 -0.04"/><axis xyz="0 0 1"/></joint><transmission name="front_left_wheel_trans"><type>transmission_interface/SimpleTransmission</type><joint name="front_left_wheel_joint"><hardwareInterface>hardware_interface/VelocityJointInterface</hardwareInterface></joint><actuator name="front_left_wheel_motor"><mechanicalReduction>1</mechanicalReduction></actuator></transmission><link name="rear_right_wheel"><visual><geometry><cylinder length="0.04" radius="0.05"/></geometry><material name="black"><color rgba="0 0 0 1"/></material></visual><collision><geometry><cylinder length="0.04" radius="0.05"/></geometry></collision><inertial><mass value="0.25"/><inertia ixx="0.001" ixy="0" ixz="0" iyy="0.001" iyz="0" izz="0.001"/></inertial></link><joint name="rear_right_wheel_joint" type="continuous"><parent link="base_link"/><child link="rear_right_wheel"/><origin rpy="1.5707963267948966 0 0" xyz="-0.15 -0.16999999999999998 -0.04"/><axis xyz="0 0 1"/></joint><transmission name="rear_right_wheel_trans"><type>transmission_interface/SimpleTransmission</type><joint name="rear_right_wheel_joint"><hardwareInterface>hardware_interface/VelocityJointInterface</hardwareInterface></joint><actuator name="rear_right_wheel_motor"><mechanicalReduction>1</mechanicalReduction></actuator></transmission><link name="rear_left_wheel"><visual><geometry><cylinder length="0.04" radius="0.05"/></geometry><material name="black"><color rgba="0 0 0 1"/></material></visual><collision><geometry><cylinder length="0.04" radius="0.05"/></geometry></collision><inertial><mass value="0.25"/><inertia ixx="0.001" ixy="0" ixz="0" iyy="0.001" iyz="0" izz="0.001"/></inertial></link><joint name="rear_left_wheel_joint" type="continuous"><parent link="base_link"/><child link="rear_left_wheel"/><origin rpy="1.5707963267948966 0 0" xyz="-0.15 0.16999999999999998 -0.04"/><axis xyz="0 0 1"/></joint><transmission name="rear_left_wheel_trans"><type>transmission_interface/SimpleTransmission</type><joint name="rear_left_wheel_joint"><hardwareInterface>hardware_interface/VelocityJointInterface</hardwareInterface></joint><actuator name="rear_left_wheel_motor"><mechanicalReduction>1</mechanicalReduction></actuator></transmission><plugin filename="libgazebo_ros_diff_drive.so" name="diff_drive_controller"><update_rate>50</update_rate><left_joint>left_wheel_joint</left_joint><right_joint>right_wheel_joint</right_joint><wheel_separation>0.35</wheel_separation><wheel_diameter>0.1</wheel_diameter><max_wheel_torque>200</max_wheel_torque><max_wheel_acceleration>10.0</max_wheel_acceleration><command_topic>cmd_vel</command_topic><publish_odom>true</publish_odom><publish_odom_tf>true</publish_odom_tf><odometry_topic>odom</odometry_topic><robot_base_frame>base_link</robot_base_frame><odometry_frame>odom</odometry_frame></plugin></robot>